Workbook

Sheet Master Question Bank
A1: QuestionID | B1: QuestionText | C1: SoftControl | D1: Response | E1: Score Scale | F1: Score_100
A2: Q001 | B2: I believe that my Leaders and seniors are positive role models when it comes to successfully managing all potential risks | C2: Role Modelling | D2: Disagree | E2: =IF(tblQuestions[[#This Row],[Response]]="","",VALUE(CHOOSE(MATCH(tblQuestions[[#This Row],[Response]],{"Strongly Agree","Agree","Neutral","Disagree","Strongly Disagree"},0),5,4,3,2,1))) -> 2 | F2: =IF(tblQuestions[[#This Row],[Score Scale]]="","",tblQuestions[[#This Row],[Score Scale]]*20) -> 40
A3: Q002 | B3: All the executives set the right ‘tone at the top’ on the importance of managing all potential risks. | C3: Role Modelling | D3: Strongly Agree | E3: =IF(tblQuestions[[#This Row],[Response]]="","",VALUE(CHOOSE(MATCH(tblQuestions[[#This Row],[Response]],{"Strongly Agree","Agree","Neutral","Disagree","Strongly Disagree"},0),5,4,3,2,1))) -> 5 | F3: =IF(tblQuestions[[#This Row],[Score Scale]]="","",tblQuestions[[#This Row],[Score Scale]]*20) -> 100
A4: Q003 | B4: All the seniors encourage employees to identify, escalate and report all material potential risks in a timely manner | C4: Role Modelling | D4: Agree | E4: =IF(tblQuestions[[#This Row],[Response]]="","",VALUE(CHOOSE(MATCH(tblQuestions[[#This Row],[Response]],{"Strongly Agree","Agree","Neutral","Disagree","Strongly Disagree"},0),5,4,3,2,1))) -> 4 | F4: =IF(tblQuestions[[#This Row],[Score Scale]]="","",tblQuestions[[#This Row],[Score Scale]]*20) -> 80
A5: Q004 | B5: When decisions are made by leaders, potential and long-term implications are usually considered. | C5: Role Modelling | D5: Disagree | E5: =IF(tblQuestions[[#This Row],[Response]]="","",VALUE(CHOOSE(MATCH(tblQuestions[[#This Row],[Response]],{"Strongly Agree","Agree","Neutral","Disagree","Strongly Disagree"},0),5,4,3,2,1))) -> 2 | F5: =IF(tblQuestions[[#This Row],[Score Scale]]="","",tblQuestions[[#This Row],[Score Scale]]*20) -> 40
A6: Q005 | B6: In a Team or with leaders we can discuss openly when results fall short,and expectations aren’t met. | C6: Discussability | D6: Agree | E6: =IF(tblQuestions[[#This Row],[Response]]="","",VALUE(CHOOSE(MATCH(tblQuestions[[#This Row],[Response]],{"Strongly Agree","Agree","Neutral","Disagree","Strongly Disagree"},0),5,4,3,2,1))) -> 4 | F6: =IF(tblQuestions[[#This Row],[Score Scale]]="","",tblQuestions[[#This Row],[Score Scale]]*20) -> 80
A7: Q006 | B7: People can seek advice if they have questions about managing tasks or risks in the team. | C7: Discussability | D7: Disagree | E7: =IF(tblQuestions[[#This Row],[Response]]="","",VALUE(CHOOSE(MATCH(tblQuestions[[#This Row],[Response]],{"Strongly Agree","Agree","Neutral","Disagree","Strongly Disagree"},0),5,4,3,2,1))) -> 2 | F7: =IF(tblQuestions[[#This Row],[Score Scale]]="","",tblQuestions[[#This Row],[Score Scale]]*20) -> 40
A8: Q007 | B8: People feel comfortable sharing their opinion on work and risk management. | C8: Discussability | D8: Neutral | E8: =IF(tblQuestions[[#This Row],[Response]]="","",VALUE(CHOOSE(MATCH(tblQuestions[[#This Row],[Response]],{"Strongly Agree","Agree","Neutral","Disagree","Strongly Disagree"},0),5,4,3,2,1))) -> 3 | F8: =IF(tblQuestions[[#This Row],[Score Scale]]="","",tblQuestions[[#This Row],[Score Scale]]*20) -> 60
A9: Q008 | B9: Within my team or department people feel comfortable to report risk management dillemas or if something goes wrong. | C9: Discussability | D9: Strongly Disagree | E9: =IF(tblQuestions[[#This Row],[Response]]="","",VALUE(CHOOSE(MATCH(tblQuestions[[#This Row],[Response]],{"Strongly Agree","Agree","Neutral","Disagree","Strongly Disagree"},0),5,4,3,2,1))) -> 1 | F9: =IF(tblQuestions[[#This Row],[Score Scale]]="","",tblQuestions[[#This Row],[Score Scale]]*20) -> 20
A10: Q009 | B10: The amount of training in risk management I have received to help me manage risk in my job is sufficient. | C10: Achievability | D10: Strongly Disagree | E10: =IF(tblQuestions[[#This Row],[Response]]="","",VALUE(CHOOSE(MATCH(tblQuestions[[#This Row],[Response]],{"Strongly Agree","Agree","Neutral","Disagree","Strongly Disagree"},0),5,4,3,2,1))) -> 1 | F10: =IF(tblQuestions[[#This Row],[Score Scale]]="","",tblQuestions[[#This Row],[Score Scale]]*20) -> 20
A11: Q010 | B11: Within my team or department people have enough time and resources to do their job without taking unacceptable risks | C11: Achievability | D11: Disagree | E11: =IF(tblQuestions[[#This Row],[Response]]="","",VALUE(CHOOSE(MATCH(tblQuestions[[#This Row],[Response]],{"Strongly Agree","Agree","Neutral","Disagree","Strongly Disagree"},0),5,4,3,2,1))) -> 2 | F11: =IF(tblQuestions[[#This Row],[Score Scale]]="","",tblQuestions[[#This Row],[Score Scale]]*20) -> 40
A12: Q011 | B12: People set targets that are achievable without compromising risk management policies, guidelines and procedures. | C12: Achievability | D12: Neutral | E12: =IF(tblQuestions[[#This Row],[Response]]="","",VALUE(CHOOSE(MATCH(tblQuestions[[#This Row],[Response]],{"Strongly Agree","Agree","Neutral","Disagree","Strongly Disagree"},0),5,4,3,2,1))) -> 3 | F12: =IF(tblQuestions[[#This Row],[Score Scale]]="","",tblQuestions[[#This Row],[Score Scale]]*20) -> 60
A13: Q012 | B13: People visibly consider potential risks when making strategic decisions | C13: Achievability | D13: Neutral | E13: =IF(tblQuestions[[#This Row],[Response]]="","",VALUE(CHOOSE(MATCH(tblQuestions[[#This Row],[Response]],{"Strongly Agree","Agree","Neutral","Disagree","Strongly Disagree"},0),5,4,3,2,1))) -> 3 | F13: =IF(tblQuestions[[#This Row],[Score Scale]]="","",tblQuestions[[#This Row],[Score Scale]]*20) -> 60
... A33: Q032 | B33: Within my team at workplace, people are receptive to criticism on their own conduct. | C33: Call someone to account | D33: Agree | E33: =IF(tblQuestions[[#This Row],[Response]]="","",VALUE(CHOOSE(MATCH(tblQuestions[[#This Row],[Response]],{"Strongly Agree","Agree","Neutral","Disagree","Strongly Disagree"},0),5,4,3,2,1))) -> 4 | F33: =IF(tblQuestions[[#This Row],[Score Scale]]="","",tblQuestions[[#This Row],[Score Scale]]*20) -> 80
A34: Q033 | B34: Did you experienced or witnessed a violation of company values or the Code of Conduct within the last twelve months | F34: =IF(tblQuestions[[#This Row],[Score Scale]]="","",tblQuestions[[#This Row],[Score Scale]]*20)
A35: Q034 | B35: To whom would you like to report undesired behavior instances happening in you organization | F35: =IF(tblQuestions[[#This Row],[Score Scale]]="","",tblQuestions[[#This Row],[Score Scale]]*20)

Sheet FinalQuestions
A1: QuestionID | B1: QuestionText | C1: SoftControl | D1: Dimensions | E1: What it means to your organization | F1: Business Impact | G1: High Risk Statements | H1: Med Risk Statements | I1: Low Risk Statements | J1: Flagged
A2: Q001 | B2: I believe that my leaders and senior managers consistently act as positive role models, also when they are under time pressure or facing difficult trade‑offs. | C2: Role Modelling | D2: Leadership Example‑Setting in Risk Management | E2: It reflects how consistently leaders demonstrate risk‑aware behavior through their decisions and day‑to‑day actions. | F2: When this is low, employees receive mixed signals about expected behavior, leading to inconsistency, reduced trust in leadership, and weaker cultural alignment. | G2: Leaders are not consistently demonstrating expected risk‑aware behavior. This creates confusion within teams about what is acceptable and weakens trust in leadership decisions. | H2: Leadership intent is understood, but behaviors are not consistently demonstrated across levels. This may lead to pockets of inconsistency and uneven culture adoption. | I2: Leaders consistently role‑model strong risk‑aware behaviors. This sets clear expectations and strongly reinforces the desired culture across the organization. | J2: No
A3: Q002 | B3: Leaders openly emphasize the importance of doing things the right way, even under time pressure | C3: Role Modelling | D3: Executive Commitment to Risk Culture | E3: Shows how visibly senior leadership prioritizes and reinforces a strong risk culture. | F3: Low commitment reduces the credibility of risk initiatives, slows cultural adoption, and causes employees to deprioritize risk considerations. | G3: Senior leadership support for risk culture is perceived as weak or inconsistent. As a result, employees deprioritize risk considerations in daily decisions. | H3: Executives communicate commitment to risk culture, but reinforcement is not always visible. Cultural momentum exists but lacks strong top‑down reinforcement. | I3: Executive leadership visibly prioritizes and reinforces risk culture. This drives strong alignment and reinforces consistent behavior across functions. | J3: Yes
A4: Q003 | B4: All the seniors encourage employees to identify, escalate and report all the concerns in a timely manner | C4: Role Modelling | D4: Leadership Encouragement to Escalate Risks | E4: Indicates whether leaders actively encourage employees to raise concerns and escalate risks early. | F4: Low scores result in hidden risks, delayed escalation, and higher likelihood of issues growing into serious incidents. | G4: Employees do not feel encouraged to raise concerns, resulting in risks remaining hidden until they escalate into major issues. | H4: Employees escalate certain issues but may hesitate in sensitive situations. Early warning signals may still be missed. | I4: Leaders actively encourage escalation, enabling early detection and timely resolution of risks. | J4: No
A5: Q004 | B5: When decisions are made by leaders, potential and long-term implications are usually considered. | C5: Role Modelling | D5: Long-Term Decision Awareness | E5: Measures the extent to which decisions consider long‑term consequences beyond immediate pressures. | F5: Low awareness leads to short‑term decision‑making, recurring problems, and misalignment with long‑term strategy. | G5: Decisions are driven primarily by short‑term pressure, increasing the likelihood of repeated problems and strategic misalignment. | H5: Long‑term implications are considered in some decisions, but consistency is lacking under operational pressure. | I5: Decisions consistently account for long‑term impact, supporting sustainable performance and risk management. | J5: Yes
A6: Q005 | B6: Differences of opinion are respected during discussions about judgments or decisions | C6: Discussability | D6: Openness to Discussions | E6: Reflects how freely employees can discuss concerns, mistakes, and dilemmas. | F6: Low openness suppresses learning, limits problem‑solving, and allows unresolved issues to accumulate. | G6: Employees are reluctant to discuss concerns or mistakes, limiting learning and increasing unresolved risks. | H6: Open discussions occur in some teams but are not consistent across the organization. | I6: Employees freely discuss issues and dilemmas, enabling continuous learning and early risk identification. | J6: Yes
A7: Q006 | B7: I can openly raise concerns without fear of negative consequences | C7: Discussability | D7: Access to Guidance | E7: Shows how easily employees can obtain advice or guidance when facing risk‑related situations | F7: Poor access increases uncertainty, inconsistent decisions, and operational inefficiencies. | G7: Employees struggle to obtain guidance, leading to uncertainty and inconsistent handling of risks. | H7: Guidance is available but not always timely or clear enough for effective decision‑making. | I7: Employees have easy access to guidance, supporting confident and consistent risk decisions. | J7: No
A8: Q007 | B8: Colleagues respond constructively when mistakes or concerns are raised management. | C8: Discussability | D8: Openness to Sharing Opinions | E8: Measures whether employees feel comfortable sharing views and perspectives on risk matters. | F8: Low openness reduces diversity of input, weakens decision quality, and limits early identification of risks. | G8: Employees hesitate to share opinions, limiting diverse perspectives and increasing the chance of blind spots. | H8: Opinions are shared selectively, and some perspectives may remain unheard. | I8: Employees openly share views, strengthening decision quality and risk awareness. | J8: Yes
A9: Q008 | B9: I feel comfortable escalating issues to Risk Management / Ethics & Independence / DPP when needed | C9: Discussability | D9: Comfort in Reporting Risk Dilemmas | E9: Indicates whether employees feel safe raising ethical dilemmas or complex risk situations. | F9: Low comfort discourages reporting, delays resolution, and increases exposure to unmanaged risks. | G9: Employees feel unsafe reporting dilemmas, allowing ethical and risk issues to remain unaddressed. | H9: Some dilemmas are reported, but hesitation remains around sensitive issues. | I9: Employees feel safe raising dilemmas, enabling timely guidance and resolution. | J9: No
A10: Q009 | B10: I have received enough training to handle job‑related challenges effectively. | C10: Achievability | D10: Adequacy of Risk Management Training | E10: Assesses whether employees feel sufficiently trained to manage risk appropriately. | F10: Insufficient training leads to inconsistent behavior, higher error rates, and dependence on individual experience. | G10: Training gaps leave employees ill‑equipped to manage risk, increasing errors and inconsistencies. | H10: Training exists but may not fully address practical risk scenarios. | I10: Training effectively equips employees to manage risks confidently. | J10: Yes
A11: Q010 | B11: Within my team or department people have enough time and resources to do their job without taking unacceptable risks | C11: Achievability | D11: Workload Balance & Resource Sufficiency | E11: Evaluates whether employees have enough time and resources to manage risk effectively. | F11: High workload pressure causes shortcuts, control gaps, and increased operational risk. | G11: High workload prevents employees from properly managing risks, leading to shortcuts and control gaps. | H11: Work pressure occasionally impacts risk quality but remains manageable. | I11: Workload and resources allow employees to consistently manage risks effectively. | J11: Yes
A12: Q011 | B12: People set targets that are achievable without compromising risk management policies, guidelines and procedures. | C12: Achievability | D12: Realistic Target Setting | E12: Measures whether targets and expectations are achievable without compromising risk standards. | F12: Unrealistic targets encourage risk‑taking, policy breaches, and erosion of ethical behavior. | G12: Unrealistic targets encourage risk‑taking and rule‑bypassing behavior. | H12: Targets are generally realistic, but pressure remains in certain situations. | I12: Targets support responsible behavior without compromising risk standards. | J12: Yes
... A33: Q032 | B33: Team members are held to the same behavioral standards, no matter who they are. | C33: Call someone to account | D33: Consistency of Conduct Enforcement | E33: Measures fairness and consistency in applying behavioral rules. | F33: Inconsistent enforcement erodes trust and weakens adherence to standards. | G33: Rules are applied inconsistently, eroding trust and fairness. | H33: Enforcement is generally fair but occasionally inconsistent. | I33: Consistent enforcement reinforces ethical and expected behavior. | J33: Yes

Sheet Sheet2
A3: Dimension x Functions | B3: Functions
A4: Dimension | B4: Audit | C4: Finance | D4: HR | E4: IT | F4: Operations | G4: Sales | H4: Grand Total
A5: Access to Guidance | B5: 95 | C5: 85 | D5: 70 | E5: 76 | F5: 68 | G5: 75 | H5: 77.692308
A6: Accountability for Risk Actions | B6: 90 | C6: 80 | D6: 65 | E6: 76 | F6: 68 | G6: 60 | H6: 73.076923
A7: Adequacy of Risk Management Training | B7: 80 | C7: 75 | D7: 75 | E7: 72 | F7: 60 | G7: 90 | H7: 74.615385
A8: Clarity of Personal Risk Boundaries | B8: 70 | C8: 90 | D8: 80 | E8: 96 | F8: 64 | G8: 80 | H8: 80
A9: Clarity of Role and Responsibilities | B9: 65 | C9: 70 | D9: 75 | E9: 76 | F9: 64 | G9: 60 | H9: 68.461538
A10: Comfort for Reporting Non‑Compliance. | B10: 70 | C10: 70 | D10: 80 | E10: 92 | F10: 64 | G10: 80 | H10: 76.153846
A11: Comfort in Reporting Risk Dilemmas | B11: 90 | C11: 75 | D11: 85 | E11: 88 | F11: 60 | G11: 85 | H11: 80
A12: Compliance Confidence in team | B12: 70 | C12: 85 | D12: 85 | E12: 56 | F12: 64 | G12: 80 | H12: 72.307692
A13: Compliance Recognition & enforcement | B13: 80 | C13: 85 | D13: 75 | E13: 84 | F13: 64 | G13: 80 | H13: 77.692308
A14: Consideration of Impact on Others | B14: 85 | C14: 80 | D14: 70 | E14: 72 | F14: 68 | G14: 80 | H14: 75.384615
A15: Consistency of Conduct Enforcement | B15: 75 | C15: 60 | D15: 85 | E15: 76 | F15: 60 | G15: 75 | H15: 71.538462
A16: Effectiveness of Risk Communication & Training | B16: 75 | C16: 70 | D16: 85 | E16: 76 | F16: 64 | G16: 80 | H16: 74.615385
... A37: Grand Total | B37: 77.03125 | C37: 75.78125 | D37: 76.5625 | E37: 75.375 | F37: 65.875 | G37: 77.5 | H37: 74.375

Sheet Responses
A1: RespondentID | B1: QuestionID | C1: Response | D1: SoftControl | E1: Scores | F1: Score_100 | G1: FavorableFlag | H1: Dimensions | I1: Function
A2: R001 | B2: Q001 | C2: Strongly Agree | D2: =VLOOKUP(Table7[[#This Row],[QuestionID]], FinalQuestions!$A:$C, 3, FALSE) -> Role Modelling | E2: =IF(Table7[[#This Row],[Response]]="","",CHOOSE(MATCH(Table7[[#This Row],[Response]],{"Strongly Agree","Agree","Neutral","Disagree","Strongly Disagree","Not Applicable"},0),5,4,3,2,1,"")) -> 5 | F2: =Table7[[#This Row],[Scores]] * 20 -> 100 | G2: =IF(OR(Table7[[#This Row],[Response]]="Strongly Agree",Table7[[#This Row],[Response]]="Agree"),1,0) -> 1 | H2: =_xlfn.XLOOKUP(Table7[[#This Row],[QuestionID]], FinalQuestions!$A:$A, FinalQuestions!$D:$D,"") -> Leadership Example‑Setting in Risk Management | I2: HR
A3: R001 | B3: Q002 | C3: Disagree | D3: =VLOOKUP(Table7[[#This Row],[QuestionID]], FinalQuestions!$A:$C, 3, FALSE) -> Role Modelling | E3: =IF(Table7[[#This Row],[Response]]="","",CHOOSE(MATCH(Table7[[#This Row],[Response]],{"Strongly Agree","Agree","Neutral","Disagree","Strongly Disagree","Not Applicable"},0),5,4,3,2,1,"")) -> 2 | F3: =Table7[[#This Row],[Scores]] * 20 -> 40 | G3: =IF(OR(Table7[[#This Row],[Response]]="Strongly Agree",Table7[[#This Row],[Response]]="Agree"),1,0) -> 0 | H3: =_xlfn.XLOOKUP(Table7[[#This Row],[QuestionID]], FinalQuestions!$A:$A, FinalQuestions!$D:$D,"") -> Executive Commitment to Risk Culture | I3: HR
A4: R001 | B4: Q003 | C4: Strongly Agree | D4: =VLOOKUP(Table7[[#This Row],[QuestionID]], FinalQuestions!$A:$C, 3, FALSE) -> Role Modelling | E4: =IF(Table7[[#This Row],[Response]]="","",CHOOSE(MATCH(Table7[[#This Row],[Response]],{"Strongly Agree","Agree","Neutral","Disagree","Strongly Disagree","Not Applicable"},0),5,4,3,2,1,"")) -> 5 | F4: =Table7[[#This Row],[Scores]] * 20 -> 100 | G4: =IF(OR(Table7[[#This Row],[Response]]="Strongly Agree",Table7[[#This Row],[Response]]="Agree"),1,0) -> 1 | H4: =_xlfn.XLOOKUP(Table7[[#This Row],[QuestionID]], FinalQuestions!$A:$A, FinalQuestions!$D:$D,"") -> Leadership Encouragement to Escalate Risks | I4: HR
A5: R001 | B5: Q004 | C5: Strongly Agree | D5: =VLOOKUP(Table7[[#This Row],[QuestionID]], FinalQuestions!$A:$C, 3, FALSE) -> Role Modelling | E5: =IF(Table7[[#This Row],[Response]]="","",CHOOSE(MATCH(Table7[[#This Row],[Response]],{"Strongly Agree","Agree","Neutral","Disagree","Strongly Disagree","Not Applicable"},0),5,4,3,2,1,"")) -> 5 | F5: =Table7[[#This Row],[Scores]] * 20 -> 100 | G5: =IF(OR(Table7[[#This Row],[Response]]="Strongly Agree",Table7[[#This Row],[Response]]="Agree"),1,0) -> 1 | H5: =_xlfn.XLOOKUP(Table7[[#This Row],[QuestionID]], FinalQuestions!$A:$A, FinalQuestions!$D:$D,"") -> Long-Term Decision Awareness | I5: HR
A6: R001 | B6: Q005 | C6: Strongly Agree | D6: =VLOOKUP(Table7[[#This Row],[QuestionID]], FinalQuestions!$A:$C, 3, FALSE) -> Discussability | E6: =IF(Table7[[#This Row],[Response]]="","",CHOOSE(MATCH(Table7[[#This Row],[Response]],{"Strongly Agree","Agree","Neutral","Disagree","Strongly Disagree","Not Applicable"},0),5,4,3,2,1,"")) -> 5 | F6: =Table7[[#This Row],[Scores]] * 20 -> 100 | G6: =IF(OR(Table7[[#This Row],[Response]]="Strongly Agree",Table7[[#This Row],[Response]]="Agree"),1,0) -> 1 | H6: =_xlfn.XLOOKUP(Table7[[#This Row],[QuestionID]], FinalQuestions!$A:$A, FinalQuestions!$D:$D,"") -> Openness to Discussions | I6: HR
A7: R001 | B7: Q006 | C7: Strongly Agree | D7: =VLOOKUP(Table7[[#This Row],[QuestionID]], FinalQuestions!$A:$C, 3, FALSE) -> Discussability | E7: =IF(Table7[[#This Row],[Response]]="","",CHOOSE(MATCH(Table7[[#This Row],[Response]],{"Strongly Agree","Agree","Neutral","Disagree","Strongly Disagree","Not Applicable"},0),5,4,3,2,1,"")) -> 5 | F7: =Table7[[#This Row],[Scores]] * 20 -> 100 | G7: =IF(OR(Table7[[#This Row],[Response]]="Strongly Agree",Table7[[#This Row],[Response]]="Agree"),1,0) -> 1 | H7: =_xlfn.XLOOKUP(Table7[[#This Row],[QuestionID]], FinalQuestions!$A:$A, FinalQuestions!$D:$D,"") -> Access to Guidance | I7: HR
A8: R001 | B8: Q007 | C8: Strongly Agree | D8: =VLOOKUP(Table7[[#This Row],[QuestionID]], FinalQuestions!$A:$C, 3, FALSE) -> Discussability | E8: =IF(Table7[[#This Row],[Response]]="","",CHOOSE(MATCH(Table7[[#This Row],[Response]],{"Strongly Agree","Agree","Neutral","Disagree","Strongly Disagree","Not Applicable"},0),5,4,3,2,1,"")) -> 5 | F8: =Table7[[#This Row],[Scores]] * 20 -> 100 | G8: =IF(OR(Table7[[#This Row],[Response]]="Strongly Agree",Table7[[#This Row],[Response]]="Agree"),1,0) -> 1 | H8: =_xlfn.XLOOKUP(Table7[[#This Row],[QuestionID]], FinalQuestions!$A:$A, FinalQuestions!$D:$D,"") -> Openness to Sharing Opinions | I8: HR
A9: R001 | B9: Q008 | C9: Strongly Agree | D9: =VLOOKUP(Table7[[#This Row],[QuestionID]], FinalQuestions!$A:$C, 3, FALSE) -> Discussability | E9: =IF(Table7[[#This Row],[Response]]="","",CHOOSE(MATCH(Table7[[#This Row],[Response]],{"Strongly Agree","Agree","Neutral","Disagree","Strongly Disagree","Not Applicable"},0),5,4,3,2,1,"")) -> 5 | F9: =Table7[[#This Row],[Scores]] * 20 -> 100 | G9: =IF(OR(Table7[[#This Row],[Response]]="Strongly Agree",Table7[[#This Row],[Response]]="Agree"),1,0) -> 1 | H9: =_xlfn.XLOOKUP(Table7[[#This Row],[QuestionID]], FinalQuestions!$A:$A, FinalQuestions!$D:$D,"") -> Comfort in Reporting Risk Dilemmas | I9: HR
A10: R001 | B10: Q009 | C10: Strongly Agree | D10: =VLOOKUP(Table7[[#This Row],[QuestionID]], FinalQuestions!$A:$C, 3, FALSE) -> Achievability | E10: =IF(Table7[[#This Row],[Response]]="","",CHOOSE(MATCH(Table7[[#This Row],[Response]],{"Strongly Agree","Agree","Neutral","Disagree","Strongly Disagree","Not Applicable"},0),5,4,3,2,1,"")) -> 5 | F10: =Table7[[#This Row],[Scores]] * 20 -> 100 | G10: =IF(OR(Table7[[#This Row],[Response]]="Strongly Agree",Table7[[#This Row],[Response]]="Agree"),1,0) -> 1 | H10: =_xlfn.XLOOKUP(Table7[[#This Row],[QuestionID]], FinalQuestions!$A:$A, FinalQuestions!$D:$D,"") -> Adequacy of Risk Management Training | I10: HR
A11: R001 | B11: Q010 | C11: Strongly Agree | D11: =VLOOKUP(Table7[[#This Row],[QuestionID]], FinalQuestions!$A:$C, 3, FALSE) -> Achievability | E11: =IF(Table7[[#This Row],[Response]]="","",CHOOSE(MATCH(Table7[[#This Row],[Response]],{"Strongly Agree","Agree","Neutral","Disagree","Strongly Disagree","Not Applicable"},0),5,4,3,2,1,"")) -> 5 | F11: =Table7[[#This Row],[Scores]] * 20 -> 100 | G11: =IF(OR(Table7[[#This Row],[Response]]="Strongly Agree",Table7[[#This Row],[Response]]="Agree"),1,0) -> 1 | H11: =_xlfn.XLOOKUP(Table7[[#This Row],[QuestionID]], FinalQuestions!$A:$A, FinalQuestions!$D:$D,"") -> Workload Balance & Resource Sufficiency | I11: HR
A12: R001 | B12: Q011 | C12: Strongly Agree | D12: =VLOOKUP(Table7[[#This Row],[QuestionID]], FinalQuestions!$A:$C, 3, FALSE) -> Achievability | E12: =IF(Table7[[#This Row],[Response]]="","",CHOOSE(MATCH(Table7[[#This Row],[Response]],{"Strongly Agree","Agree","Neutral","Disagree","Strongly Disagree","Not Applicable"},0),5,4,3,2,1,"")) -> 5 | F12: =Table7[[#This Row],[Scores]] * 20 -> 100 | G12: =IF(OR(Table7[[#This Row],[Response]]="Strongly Agree",Table7[[#This Row],[Response]]="Agree"),1,0) -> 1 | H12: =_xlfn.XLOOKUP(Table7[[#This Row],[QuestionID]], FinalQuestions!$A:$A, FinalQuestions!$D:$D,"") -> Realistic Target Setting | I12: HR
A13: R001 | B13: Q012 | C13: Strongly Agree | D13: =VLOOKUP(Table7[[#This Row],[QuestionID]], FinalQuestions!$A:$C, 3, FALSE) -> Achievability | E13: =IF(Table7[[#This Row],[Response]]="","",CHOOSE(MATCH(Table7[[#This Row],[Response]],{"Strongly Agree","Agree","Neutral","Disagree","Strongly Disagree","Not Applicable"},0),5,4,3,2,1,"")) -> 5 | F13: =Table7[[#This Row],[Scores]] * 20 -> 100 | G13: =IF(OR(Table7[[#This Row],[Response]]="Strongly Agree",Table7[[#This Row],[Response]]="Agree"),1,0) -> 1 | H13: =_xlfn.XLOOKUP(Table7[[#This Row],[QuestionID]], FinalQuestions!$A:$A, FinalQuestions!$D:$D,"") -> Risk Insight in Decision Making | I13: HR
... A833: R025 | B833: Q032 | C833: Agree | D833: =VLOOKUP(Table7[[#This Row],[QuestionID]], FinalQuestions!$A:$C, 3, FALSE) -> Call someone to account | E833: =IF(Table7[[#This Row],[Response]]="","",CHOOSE(MATCH(Table7[[#This Row],[Response]],{"Strongly Agree","Agree","Neutral","Disagree","Strongly Disagree","Not Applicable"},0),5,4,3,2,1,"")) -> 4 | F833: =Table7[[#This Row],[Scores]] * 20 -> 80 | G833: =IF(OR(Table7[[#This Row],[Response]]="Strongly Agree",Table7[[#This Row],[Response]]="Agree"),1,0) -> 1 | H833: =_xlfn.XLOOKUP(Table7[[#This Row],[QuestionID]], FinalQuestions!$A:$A, FinalQuestions!$D:$D,"") -> Consistency of Conduct Enforcement | I833: Finance

Sheet Function_SC
A1: Funtions x SoftControls | B1: {=TRANSPOSE(_xlfn._xlws.SORT(_xlfn.UNIQUE(_xlfn._xlws.FILTER(Responses!$D:$D,(Responses!$D:$D<>"")*(Responses!$D:$D<>"SoftControl")))))} -> Achievability | C1: Call someone to account | D1: Clarity | E1: Commitment | F1: Discussability | G1: Enforcement | H1: Role Modelling | I1: Transparency
A2: {=_xlfn._xlws.SORT(_xlfn.UNIQUE(_xlfn._xlws.FILTER(Responses!$I:$I,(Responses!$I:$I<>"")*(Responses!$I:$I<>"Function"))))} -> Audit | B2: =_xlfn.LET(_xlpm.func,$A2,_xlpm.sc,B$1,AVERAGEIFS(Responses!$F:$F,Responses!$I:$I,_xlpm.func,Responses!$D:$D,_xlpm.sc)) -> 72.5 | C2: =_xlfn.LET(_xlpm.func,$A2,_xlpm.sc,C$1,AVERAGEIFS(Responses!$F:$F,Responses!$I:$I,_xlpm.func,Responses!$D:$D,_xlpm.sc)) -> 71.25 | D2: =_xlfn.LET(_xlpm.func,$A2,_xlpm.sc,D$1,AVERAGEIFS(Responses!$F:$F,Responses!$I:$I,_xlpm.func,Responses!$D:$D,_xlpm.sc)) -> 66.25 | E2: =_xlfn.LET(_xlpm.func,$A2,_xlpm.sc,E$1,AVERAGEIFS(Responses!$F:$F,Responses!$I:$I,_xlpm.func,Responses!$D:$D,_xlpm.sc)) -> 81.25 | F2: =_xlfn.LET(_xlpm.func,$A2,_xlpm.sc,F$1,AVERAGEIFS(Responses!$F:$F,Responses!$I:$I,_xlpm.func,Responses!$D:$D,_xlpm.sc)) -> 92.5 | G2: =_xlfn.LET(_xlpm.func,$A2,_xlpm.sc,G$1,AVERAGEIFS(Responses!$F:$F,Responses!$I:$I,_xlpm.func,Responses!$D:$D,_xlpm.sc)) -> 75 | H2: =_xlfn.LET(_xlpm.func,$A2,_xlpm.sc,H$1,AVERAGEIFS(Responses!$F:$F,Responses!$I:$I,_xlpm.func,Responses!$D:$D,_xlpm.sc)) -> 81.25 | I2: =_xlfn.LET(_xlpm.func,$A2,_xlpm.sc,I$1,AVERAGEIFS(Responses!$F:$F,Responses!$I:$I,_xlpm.func,Responses!$D:$D,_xlpm.sc)) -> 76.25
A3: Finance | B3: =_xlfn.LET(_xlpm.func,$A3,_xlpm.sc,B$1,AVERAGEIFS(Responses!$F:$F,Responses!$I:$I,_xlpm.func,Responses!$D:$D,_xlpm.sc)) -> 73.75 | C3: =_xlfn.LET(_xlpm.func,$A3,_xlpm.sc,C$1,AVERAGEIFS(Responses!$F:$F,Responses!$I:$I,_xlpm.func,Responses!$D:$D,_xlpm.sc)) -> 55 | D3: =_xlfn.LET(_xlpm.func,$A3,_xlpm.sc,D$1,AVERAGEIFS(Responses!$F:$F,Responses!$I:$I,_xlpm.func,Responses!$D:$D,_xlpm.sc)) -> 81.25 | E3: =_xlfn.LET(_xlpm.func,$A3,_xlpm.sc,E$1,AVERAGEIFS(Responses!$F:$F,Responses!$I:$I,_xlpm.func,Responses!$D:$D,_xlpm.sc)) -> 73.75 | F3: =_xlfn.LET(_xlpm.func,$A3,_xlpm.sc,F$1,AVERAGEIFS(Responses!$F:$F,Responses!$I:$I,_xlpm.func,Responses!$D:$D,_xlpm.sc)) -> 80 | G3: =_xlfn.LET(_xlpm.func,$A3,_xlpm.sc,G$1,AVERAGEIFS(Responses!$F:$F,Responses!$I:$I,_xlpm.func,Responses!$D:$D,_xlpm.sc)) -> 80 | H3: =_xlfn.LET(_xlpm.func,$A3,_xlpm.sc,H$1,AVERAGEIFS(Responses!$F:$F,Responses!$I:$I,_xlpm.func,Responses!$D:$D,_xlpm.sc)) -> 80 | I3: =_xlfn.LET(_xlpm.func,$A3,_xlpm.sc,I$1,AVERAGEIFS(Responses!$F:$F,Responses!$I:$I,_xlpm.func,Responses!$D:$D,_xlpm.sc)) -> 82.5
A4: HR | B4: =_xlfn.LET(_xlpm.func,$A4,_xlpm.sc,B$1,AVERAGEIFS(Responses!$F:$F,Responses!$I:$I,_xlpm.func,Responses!$D:$D,_xlpm.sc)) -> 76.25 | C4: =_xlfn.LET(_xlpm.func,$A4,_xlpm.sc,C$1,AVERAGEIFS(Responses!$F:$F,Responses!$I:$I,_xlpm.func,Responses!$D:$D,_xlpm.sc)) -> 76.25 | D4: =_xlfn.LET(_xlpm.func,$A4,_xlpm.sc,D$1,AVERAGEIFS(Responses!$F:$F,Responses!$I:$I,_xlpm.func,Responses!$D:$D,_xlpm.sc)) -> 80 | E4: =_xlfn.LET(_xlpm.func,$A4,_xlpm.sc,E$1,AVERAGEIFS(Responses!$F:$F,Responses!$I:$I,_xlpm.func,Responses!$D:$D,_xlpm.sc)) -> 75 | F4: =_xlfn.LET(_xlpm.func,$A4,_xlpm.sc,F$1,AVERAGEIFS(Responses!$F:$F,Responses!$I:$I,_xlpm.func,Responses!$D:$D,_xlpm.sc)) -> 76.25 | G4: =_xlfn.LET(_xlpm.func,$A4,_xlpm.sc,G$1,AVERAGEIFS(Responses!$F:$F,Responses!$I:$I,_xlpm.func,Responses!$D:$D,_xlpm.sc)) -> 76.25 | H4: =_xlfn.LET(_xlpm.func,$A4,_xlpm.sc,H$1,AVERAGEIFS(Responses!$F:$F,Responses!$I:$I,_xlpm.func,Responses!$D:$D,_xlpm.sc)) -> 75 | I4: =_xlfn.LET(_xlpm.func,$A4,_xlpm.sc,I$1,AVERAGEIFS(Responses!$F:$F,Responses!$I:$I,_xlpm.func,Responses!$D:$D,_xlpm.sc)) -> 77.5
A5: IT | B5: =_xlfn.LET(_xlpm.func,$A5,_xlpm.sc,B$1,AVERAGEIFS(Responses!$F:$F,Responses!$I:$I,_xlpm.func,Responses!$D:$D,_xlpm.sc)) -> 71 | C5: =_xlfn.LET(_xlpm.func,$A5,_xlpm.sc,C$1,AVERAGEIFS(Responses!$F:$F,Responses!$I:$I,_xlpm.func,Responses!$D:$D,_xlpm.sc)) -> 80 | D5: =_xlfn.LET(_xlpm.func,$A5,_xlpm.sc,D$1,AVERAGEIFS(Responses!$F:$F,Responses!$I:$I,_xlpm.func,Responses!$D:$D,_xlpm.sc)) -> 83 | E5: =_xlfn.LET(_xlpm.func,$A5,_xlpm.sc,E$1,AVERAGEIFS(Responses!$F:$F,Responses!$I:$I,_xlpm.func,Responses!$D:$D,_xlpm.sc)) -> 72 | F5: =_xlfn.LET(_xlpm.func,$A5,_xlpm.sc,F$1,AVERAGEIFS(Responses!$F:$F,Responses!$I:$I,_xlpm.func,Responses!$D:$D,_xlpm.sc)) -> 78 | G5: =_xlfn.LET(_xlpm.func,$A5,_xlpm.sc,G$1,AVERAGEIFS(Responses!$F:$F,Responses!$I:$I,_xlpm.func,Responses!$D:$D,_xlpm.sc)) -> 75 | H5: =_xlfn.LET(_xlpm.func,$A5,_xlpm.sc,H$1,AVERAGEIFS(Responses!$F:$F,Responses!$I:$I,_xlpm.func,Responses!$D:$D,_xlpm.sc)) -> 74 | I5: =_xlfn.LET(_xlpm.func,$A5,_xlpm.sc,I$1,AVERAGEIFS(Responses!$F:$F,Responses!$I:$I,_xlpm.func,Responses!$D:$D,_xlpm.sc)) -> 70
A6: Operations | B6: =_xlfn.LET(_xlpm.func,$A6,_xlpm.sc,B$1,AVERAGEIFS(Responses!$F:$F,Responses!$I:$I,_xlpm.func,Responses!$D:$D,_xlpm.sc)) -> 60 | C6: =_xlfn.LET(_xlpm.func,$A6,_xlpm.sc,C$1,AVERAGEIFS(Responses!$F:$F,Responses!$I:$I,_xlpm.func,Responses!$D:$D,_xlpm.sc)) -> 64 | D6: =_xlfn.LET(_xlpm.func,$A6,_xlpm.sc,D$1,AVERAGEIFS(Responses!$F:$F,Responses!$I:$I,_xlpm.func,Responses!$D:$D,_xlpm.sc)) -> 64 | E6: =_xlfn.LET(_xlpm.func,$A6,_xlpm.sc,E$1,AVERAGEIFS(Responses!$F:$F,Responses!$I:$I,_xlpm.func,Responses!$D:$D,_xlpm.sc)) -> 70 | F6: =_xlfn.LET(_xlpm.func,$A6,_xlpm.sc,F$1,AVERAGEIFS(Responses!$F:$F,Responses!$I:$I,_xlpm.func,Responses!$D:$D,_xlpm.sc)) -> 66 | G6: =_xlfn.LET(_xlpm.func,$A6,_xlpm.sc,G$1,AVERAGEIFS(Responses!$F:$F,Responses!$I:$I,_xlpm.func,Responses!$D:$D,_xlpm.sc)) -> 67 | H6: =_xlfn.LET(_xlpm.func,$A6,_xlpm.sc,H$1,AVERAGEIFS(Responses!$F:$F,Responses!$I:$I,_xlpm.func,Responses!$D:$D,_xlpm.sc)) -> 67 | I6: =_xlfn.LET(_xlpm.func,$A6,_xlpm.sc,I$1,AVERAGEIFS(Responses!$F:$F,Responses!$I:$I,_xlpm.func,Responses!$D:$D,_xlpm.sc)) -> 69
A7: Sales | B7: =_xlfn.LET(_xlpm.func,$A7,_xlpm.sc,B$1,AVERAGEIFS(Responses!$F:$F,Responses!$I:$I,_xlpm.func,Responses!$D:$D,_xlpm.sc)) -> 82.5 | C7: =_xlfn.LET(_xlpm.func,$A7,_xlpm.sc,C$1,AVERAGEIFS(Responses!$F:$F,Responses!$I:$I,_xlpm.func,Responses!$D:$D,_xlpm.sc)) -> 73.75 | D7: =_xlfn.LET(_xlpm.func,$A7,_xlpm.sc,D$1,AVERAGEIFS(Responses!$F:$F,Responses!$I:$I,_xlpm.func,Responses!$D:$D,_xlpm.sc)) -> 75 | E7: =_xlfn.LET(_xlpm.func,$A7,_xlpm.sc,E$1,AVERAGEIFS(Responses!$F:$F,Responses!$I:$I,_xlpm.func,Responses!$D:$D,_xlpm.sc)) -> 76.25 | F7: =_xlfn.LET(_xlpm.func,$A7,_xlpm.sc,F$1,AVERAGEIFS(Responses!$F:$F,Responses!$I:$I,_xlpm.func,Responses!$D:$D,_xlpm.sc)) -> 77.5 | G7: =_xlfn.LET(_xlpm.func,$A7,_xlpm.sc,G$1,AVERAGEIFS(Responses!$F:$F,Responses!$I:$I,_xlpm.func,Responses!$D:$D,_xlpm.sc)) -> 78.75 | H7: =_xlfn.LET(_xlpm.func,$A7,_xlpm.sc,H$1,AVERAGEIFS(Responses!$F:$F,Responses!$I:$I,_xlpm.func,Responses!$D:$D,_xlpm.sc)) -> 77.5 | I7: =_xlfn.LET(_xlpm.func,$A7,_xlpm.sc,I$1,AVERAGEIFS(Responses!$F:$F,Responses!$I:$I,_xlpm.func,Responses!$D:$D,_xlpm.sc)) -> 78.75
A10: Funtion | B10: RCI
A11: {=_xlfn._xlws.SORT(_xlfn.UNIQUE(_xlfn._xlws.FILTER(Responses!$I:$I,(Responses!$I:$I<>"")*(Responses!$I:$I<>"Function"))))} -> Audit | B11: =IFERROR(ROUND(AVERAGEIFS(Responses!$F:$F,Responses!$I:$I,$A2),0),"") -> 77
A12: Finance | B12: =IFERROR(ROUND(AVERAGEIFS(Responses!$F:$F,Responses!$I:$I,$A3),0),"") -> 76
A13: HR | B13: =IFERROR(ROUND(AVERAGEIFS(Responses!$F:$F,Responses!$I:$I,$A4),0),"") -> 77
A14: IT | B14: =IFERROR(ROUND(AVERAGEIFS(Responses!$F:$F,Responses!$I:$I,$A5),0),"") -> 75
A15: Operations | B15: =IFERROR(ROUND(AVERAGEIFS(Responses!$F:$F,Responses!$I:$I,$A6),0),"") -> 66
A16: Sales | B16: =IFERROR(ROUND(AVERAGEIFS(Responses!$F:$F,Responses!$I:$I,$A7),0),"") -> 78
A26: KPI | B26: Value
A27: Best Funtion | B27: =INDEX($A$10:$A$16,MATCH(MAX($B$10:$B$16),$B$10:$B$16,0))& "(" & MAX($B$10:$B$16)& ")" -> Sales(78)
A28: Worst Funtion | B28: =INDEX($A$10:$A$16, MATCH(MIN($B$10:$B$16), $B$10:$B$16, 0)) & " (" & MIN($B$10:$B$16) & ")" -> Operations (66)

Sheet Sheet1

Sheet Culture_Risk_Index
A1: Metric | B1: Value
A2: Risk Culture Index | B2: =IFERROR(AVERAGE(Responses!$F:$F), "") -> 74.375
A3: Total Respondents | B3: =COUNTA(_xlfn.UNIQUE(Responses!$A:$A)) -> 27
A4: Total Questions | B4: =COUNTA(FinalQuestions!$A:$A) - 1 -> 32
A5: Overall Favorable % | B5: =SUM(Responses!$G:$G) / COUNTA(Responses!$G:$G)*100 -> 56.182473
A6: Overall Risk Level | B6: =IF(B2>=80,"Low",IF(B2>=60,"Medium","High")) -> Medium
L9: ="RCI Score: "&TEXT(B2,"0")&"%" -> RCI Score: 74% | P9: Risk Culture Index
P10: =IFERROR(AVERAGE(Responses!$F:$F), "") -> 74.375
A34: High Risk | B34: 1.8
A35: Med Risk | B35: 0.6
A36: Low Risk | B36: 0.6
A37: Hidden | B37: 1
A38: hidden | B38: 1
A39: hidden | B39: 1
A55: Column1 | B55: Column2
A56: StartPadding | B56: =B2*1.8 -> 133.875
A57: Needle | B57: 1
A58: End Padding | B58: =360 - B56 - B57 -> 225.125
A72: SoftControl | B72: Score
A73: Role Modelling | B73: =IFERROR(ROUND(AVERAGEIFS(Responses!$F:$F,Responses!$D:$D,$A73),0),"") -> 75
A74: Discussability | B74: =IFERROR(ROUND(AVERAGEIFS(Responses!$F:$F,Responses!$D:$D,$A74),0),"") -> 78
A75: Achievability | B75: =IFERROR(ROUND(AVERAGEIFS(Responses!$F:$F,Responses!$D:$D,$A75),0),"") -> 72
A76: Enforcement | B76: =IFERROR(ROUND(AVERAGEIFS(Responses!$F:$F,Responses!$D:$D,$A76),0),"") -> 75
A77: Clarity | B77: =IFERROR(ROUND(AVERAGEIFS(Responses!$F:$F,Responses!$D:$D,$A77),0),"") -> 75
A78: Transparency | B78: =IFERROR(ROUND(AVERAGEIFS(Responses!$F:$F,Responses!$D:$D,$A78),0),"") -> 75
A79: Commitment | B79: =IFERROR(ROUND(AVERAGEIFS(Responses!$F:$F,Responses!$D:$D,$A79),0),"") -> 74
A80: Call someone to account | B80: =IFERROR(ROUND(AVERAGEIFS(Responses!$F:$F,Responses!$D:$D,$A80),0),"") -> 70

Sheet Sector benchmark score
A1: Sector | B1: Transparency | C1: Clarity | D1: Achievability | E1: Role Modelling | F1: Commitment | G1: Discussability | H1: Calling to Account | I1: Enforcement
A2: Banking & Capital Markets | B2: 78 | C2: 88 | D2: 72 | E2: 80 | F2: 82 | G2: 74 | H2: 76 | I2: 84
A3: Insurance | B3: 76 | C3: 86 | D3: 74 | E3: 79 | F3: 83 | G3: 73 | H3: 75 | I3: 83
A4: Technology, Media & Telecom | B4: 72 | C4: 80 | D4: 70 | E4: 77 | F4: 85 | G4: 82 | H4: 68 | I4: 72
A5: Healthcare & Life Sciences | B5: 70 | C5: 84 | D5: 68 | E5: 78 | F5: 87 | G5: 72 | H5: 70 | I5: 76
A6: Energy & Natural Resources | B6: 68 | C6: 82 | D6: 66 | E6: 76 | F6: 80 | G6: 70 | H6: 72 | I6: 78
A7: Government & Public Sector | B7: 66 | C7: 85 | D7: 60 | E7: 74 | F7: 79 | G7: 69 | H7: 65 | I7: 73
A8: Consumer Goods & Retail | B8: 72 | C8: 82 | D8: 71 | E8: 76 | F8: 81 | G8: 74 | H8: 69 | I8: 71
A9: Industrial Manufacturing | B9: 70 | C9: 84 | D9: 72 | E9: 75 | F9: 80 | G9: 68 | H9: 73 | I9: 77
A10: Infrastructure & Transport | B10: 69 | C10: 83 | D10: 65 | E10: 74 | F10: 78 | G10: 67 | H10: 72 | I10: 76
A11: Real Estate & Construction | B11: 68 | C11: 81 | D11: 64 | E11: 73 | F11: 77 | G11: 66 | H11: 70 | I11: 74

Sheet Summary
A1: RespondentID | B1: SoftControl | C1: Avg Scores | D1: AvgScore100 | E1: Favorable% | F1: Total_Qs
A2: R001 | B2: Role Modelling | C2: =IFERROR(AVERAGEIFS(Responses!$E:$E,Responses!$A:$A,$A2,Responses!$D:$D,$B2),"") -> 4.25 | D2: =IFERROR(AVERAGEIFS(Responses!$F:$F,Responses!$A:$A,$A2,Responses!$D:$D,$B2),"") -> 85 | E2: =IFERROR(SUMIFS(Responses!$G:$G,Responses!$A:$A,$A2,Responses!$D:$D,$B2)/COUNTIFS(Responses!$A:$A,$A2,Responses!$D:$D,$B2),0)*100 -> 75 | F2: =COUNTIFS(Responses!$A:$A,$A2,Responses!$D:$D,$B2) -> 4
A3: R001 | B3: Discussability | C3: =IFERROR(AVERAGEIFS(Responses!$E:$E,Responses!$A:$A,$A3,Responses!$D:$D,$B3),"") -> 5 | D3: =IFERROR(AVERAGEIFS(Responses!$F:$F,Responses!$A:$A,$A3,Responses!$D:$D,$B3),"") -> 100 | E3: =IFERROR(SUMIFS(Responses!$G:$G,Responses!$A:$A,$A3,Responses!$D:$D,$B3)/COUNTIFS(Responses!$A:$A,$A3,Responses!$D:$D,$B3),0)*100 -> 100 | F3: =COUNTIFS(Responses!$A:$A,$A3,Responses!$D:$D,$B3) -> 4
A4: R001 | B4: Achievability | C4: =IFERROR(AVERAGEIFS(Responses!$E:$E,Responses!$A:$A,$A4,Responses!$D:$D,$B4),"") -> 5 | D4: =IFERROR(AVERAGEIFS(Responses!$F:$F,Responses!$A:$A,$A4,Responses!$D:$D,$B4),"") -> 100 | E4: =IFERROR(SUMIFS(Responses!$G:$G,Responses!$A:$A,$A4,Responses!$D:$D,$B4)/COUNTIFS(Responses!$A:$A,$A4,Responses!$D:$D,$B4),0)*100 -> 100 | F4: =COUNTIFS(Responses!$A:$A,$A4,Responses!$D:$D,$B4) -> 4
A5: R001 | B5: Enforcement | C5: =IFERROR(AVERAGEIFS(Responses!$E:$E,Responses!$A:$A,$A5,Responses!$D:$D,$B5),"") -> 5 | D5: =IFERROR(AVERAGEIFS(Responses!$F:$F,Responses!$A:$A,$A5,Responses!$D:$D,$B5),"") -> 100 | E5: =IFERROR(SUMIFS(Responses!$G:$G,Responses!$A:$A,$A5,Responses!$D:$D,$B5)/COUNTIFS(Responses!$A:$A,$A5,Responses!$D:$D,$B5),0)*100 -> 100 | F5: =COUNTIFS(Responses!$A:$A,$A5,Responses!$D:$D,$B5) -> 4
A6: R001 | B6: Clarity | C6: =IFERROR(AVERAGEIFS(Responses!$E:$E,Responses!$A:$A,$A6,Responses!$D:$D,$B6),"") -> 5 | D6: =IFERROR(AVERAGEIFS(Responses!$F:$F,Responses!$A:$A,$A6,Responses!$D:$D,$B6),"") -> 100 | E6: =IFERROR(SUMIFS(Responses!$G:$G,Responses!$A:$A,$A6,Responses!$D:$D,$B6)/COUNTIFS(Responses!$A:$A,$A6,Responses!$D:$D,$B6),0)*100 -> 100 | F6: =COUNTIFS(Responses!$A:$A,$A6,Responses!$D:$D,$B6) -> 4
A7: R001 | B7: Transparency | C7: =IFERROR(AVERAGEIFS(Responses!$E:$E,Responses!$A:$A,$A7,Responses!$D:$D,$B7),"") -> 5 | D7: =IFERROR(AVERAGEIFS(Responses!$F:$F,Responses!$A:$A,$A7,Responses!$D:$D,$B7),"") -> 100 | E7: =IFERROR(SUMIFS(Responses!$G:$G,Responses!$A:$A,$A7,Responses!$D:$D,$B7)/COUNTIFS(Responses!$A:$A,$A7,Responses!$D:$D,$B7),0)*100 -> 100 | F7: =COUNTIFS(Responses!$A:$A,$A7,Responses!$D:$D,$B7) -> 4
A8: R001 | B8: Commitment | C8: =IFERROR(AVERAGEIFS(Responses!$E:$E,Responses!$A:$A,$A8,Responses!$D:$D,$B8),"") -> 5 | D8: =IFERROR(AVERAGEIFS(Responses!$F:$F,Responses!$A:$A,$A8,Responses!$D:$D,$B8),"") -> 100 | E8: =IFERROR(SUMIFS(Responses!$G:$G,Responses!$A:$A,$A8,Responses!$D:$D,$B8)/COUNTIFS(Responses!$A:$A,$A8,Responses!$D:$D,$B8),0)*100 -> 100 | F8: =COUNTIFS(Responses!$A:$A,$A8,Responses!$D:$D,$B8) -> 4
A9: R001 | B9: Call someone to account | C9: =IFERROR(AVERAGEIFS(Responses!$E:$E,Responses!$A:$A,$A9,Responses!$D:$D,$B9),"") -> 5 | D9: =IFERROR(AVERAGEIFS(Responses!$F:$F,Responses!$A:$A,$A9,Responses!$D:$D,$B9),"") -> 100 | E9: =IFERROR(SUMIFS(Responses!$G:$G,Responses!$A:$A,$A9,Responses!$D:$D,$B9)/COUNTIFS(Responses!$A:$A,$A9,Responses!$D:$D,$B9),0)*100 -> 100 | F9: =COUNTIFS(Responses!$A:$A,$A9,Responses!$D:$D,$B9) -> 4
A10: R002 | B10: Role Modelling | C10: =IFERROR(AVERAGEIFS(Responses!$E:$E,Responses!$A:$A,$A10,Responses!$D:$D,$B10),"") -> 5 | D10: =IFERROR(AVERAGEIFS(Responses!$F:$F,Responses!$A:$A,$A10,Responses!$D:$D,$B10),"") -> 100 | E10: =IFERROR(SUMIFS(Responses!$G:$G,Responses!$A:$A,$A10,Responses!$D:$D,$B10)/COUNTIFS(Responses!$A:$A,$A10,Responses!$D:$D,$B10),0)*100 -> 100 | F10: =COUNTIFS(Responses!$A:$A,$A10,Responses!$D:$D,$B10) -> 4
A11: R002 | B11: Discussability | C11: =IFERROR(AVERAGEIFS(Responses!$E:$E,Responses!$A:$A,$A11,Responses!$D:$D,$B11),"") -> 5 | D11: =IFERROR(AVERAGEIFS(Responses!$F:$F,Responses!$A:$A,$A11,Responses!$D:$D,$B11),"") -> 100 | E11: =IFERROR(SUMIFS(Responses!$G:$G,Responses!$A:$A,$A11,Responses!$D:$D,$B11)/COUNTIFS(Responses!$A:$A,$A11,Responses!$D:$D,$B11),0)*100 -> 100 | F11: =COUNTIFS(Responses!$A:$A,$A11,Responses!$D:$D,$B11) -> 4
A12: R002 | B12: Achievability | C12: =IFERROR(AVERAGEIFS(Responses!$E:$E,Responses!$A:$A,$A12,Responses!$D:$D,$B12),"") -> 5 | D12: =IFERROR(AVERAGEIFS(Responses!$F:$F,Responses!$A:$A,$A12,Responses!$D:$D,$B12),"") -> 100 | E12: =IFERROR(SUMIFS(Responses!$G:$G,Responses!$A:$A,$A12,Responses!$D:$D,$B12)/COUNTIFS(Responses!$A:$A,$A12,Responses!$D:$D,$B12),0)*100 -> 100 | F12: =COUNTIFS(Responses!$A:$A,$A12,Responses!$D:$D,$B12) -> 4
A13: R002 | B13: Enforcement | C13: =IFERROR(AVERAGEIFS(Responses!$E:$E,Responses!$A:$A,$A13,Responses!$D:$D,$B13),"") -> 5 | D13: =IFERROR(AVERAGEIFS(Responses!$F:$F,Responses!$A:$A,$A13,Responses!$D:$D,$B13),"") -> 100 | E13: =IFERROR(SUMIFS(Responses!$G:$G,Responses!$A:$A,$A13,Responses!$D:$D,$B13)/COUNTIFS(Responses!$A:$A,$A13,Responses!$D:$D,$B13),0)*100 -> 100 | F13: =COUNTIFS(Responses!$A:$A,$A13,Responses!$D:$D,$B13) -> 4
... A201: R025 | B201: Call someone to account | C201: =IFERROR(AVERAGEIFS(Responses!$E:$E,Responses!$A:$A,$A201,Responses!$D:$D,$B201),"") -> 3.5 | D201: =IFERROR(AVERAGEIFS(Responses!$F:$F,Responses!$A:$A,$A201,Responses!$D:$D,$B201),"") -> 70 | E201: =IFERROR(SUMIFS(Responses!$G:$G,Responses!$A:$A,$A201,Responses!$D:$D,$B201)/COUNTIFS(Responses!$A:$A,$A201,Responses!$D:$D,$B201),0)*100 -> 50 | F201: =COUNTIFS(Responses!$A:$A,$A201,Responses!$D:$D,$B201) -> 4

Sheet SOFT CONTROL SCORECARD
A1: SoftControl | B1: Avg Scores | C1: AvgScore100 | D1: Total_Questions | E1: Favorable% | F1: Risk_Level
A2: Role Modelling | B2: =AVERAGEIF(Responses!$D:$D, A2, Responses!$E:$E) -> 3.7692308 | C2: =IFERROR(ROUND(AVERAGEIF(Responses!$D:$D, A2, Responses!$F:$F), 0), "") -> 75 | D2: =COUNTIF(FinalQuestions!C:C, A2) -> 4 | E2: =SUMIFS(Responses!G:G, Responses!D:D, A2) / COUNTIFS(Responses!D:D, A2)*100 -> 58.653846 | F2: =IF(Table9[[#This Row],[AvgScore100]]>=80,"Low",IF(Table9[[#This Row],[AvgScore100]]>=70,"Medium","High")) -> Medium
A3: Discussability | B3: =AVERAGEIF(Responses!$D:$D, A3, Responses!$E:$E) -> 3.8942308 | C3: =IFERROR(ROUND(AVERAGEIF(Responses!$D:$D, A3, Responses!$F:$F), 0), "") -> 78 | D3: =COUNTIF(FinalQuestions!C:C, A3) -> 4 | E3: =SUMIFS(Responses!G:G, Responses!D:D, A3) / COUNTIFS(Responses!D:D, A3)*100 -> 61.538462 | F3: =IF(Table9[[#This Row],[AvgScore100]]>=80,"Low",IF(Table9[[#This Row],[AvgScore100]]>=70,"Medium","High")) -> Medium
A4: Achievability | B4: =AVERAGEIF(Responses!$D:$D, A4, Responses!$E:$E) -> 3.6057692 | C4: =IFERROR(ROUND(AVERAGEIF(Responses!$D:$D, A4, Responses!$F:$F), 0), "") -> 72 | D4: =COUNTIF(FinalQuestions!C:C, A4) -> 4 | E4: =SUMIFS(Responses!G:G, Responses!D:D, A4) / COUNTIFS(Responses!D:D, A4)*100 -> 53.846154 | F4: =IF(Table9[[#This Row],[AvgScore100]]>=80,"Low",IF(Table9[[#This Row],[AvgScore100]]>=70,"Medium","High")) -> Medium
A5: Enforcement | B5: =AVERAGEIF(Responses!$D:$D, A5, Responses!$E:$E) -> 3.75 | C5: =IFERROR(ROUND(AVERAGEIF(Responses!$D:$D, A5, Responses!$F:$F), 0), "") -> 75 | D5: =COUNTIF(FinalQuestions!C:C, A5) -> 4 | E5: =SUMIFS(Responses!G:G, Responses!D:D, A5) / COUNTIFS(Responses!D:D, A5)*100 -> 55.769231 | F5: =IF(Table9[[#This Row],[AvgScore100]]>=80,"Low",IF(Table9[[#This Row],[AvgScore100]]>=70,"Medium","High")) -> Medium
A6: Clarity | B6: =AVERAGEIF(Responses!$D:$D, A6, Responses!$E:$E) -> 3.7403846 | C6: =IFERROR(ROUND(AVERAGEIF(Responses!$D:$D, A6, Responses!$F:$F), 0), "") -> 75 | D6: =COUNTIF(FinalQuestions!C:C, A6) -> 4 | E6: =SUMIFS(Responses!G:G, Responses!D:D, A6) / COUNTIFS(Responses!D:D, A6)*100 -> 54.807692 | F6: =IF(Table9[[#This Row],[AvgScore100]]>=80,"Low",IF(Table9[[#This Row],[AvgScore100]]>=70,"Medium","High")) -> Medium
A7: Transparency | B7: =AVERAGEIF(Responses!$D:$D, A7, Responses!$E:$E) -> 3.7596154 | C7: =IFERROR(ROUND(AVERAGEIF(Responses!$D:$D, A7, Responses!$F:$F), 0), "") -> 75 | D7: =COUNTIF(FinalQuestions!C:C, A7) -> 4 | E7: =SUMIFS(Responses!G:G, Responses!D:D, A7) / COUNTIFS(Responses!D:D, A7)*100 -> 57.692308 | F7: =IF(Table9[[#This Row],[AvgScore100]]>=80,"Low",IF(Table9[[#This Row],[AvgScore100]]>=70,"Medium","High")) -> Medium
A8: Commitment | B8: =AVERAGEIF(Responses!$D:$D, A8, Responses!$E:$E) -> 3.7211538 | C8: =IFERROR(ROUND(AVERAGEIF(Responses!$D:$D, A8, Responses!$F:$F), 0), "") -> 74 | D8: =COUNTIF(FinalQuestions!C:C, A8) -> 4 | E8: =SUMIFS(Responses!G:G, Responses!D:D, A8) / COUNTIFS(Responses!D:D, A8)*100 -> 58.653846 | F8: =IF(Table9[[#This Row],[AvgScore100]]>=80,"Low",IF(Table9[[#This Row],[AvgScore100]]>=70,"Medium","High")) -> Medium
A9: Call Someone to Account | B9: =AVERAGEIF(Responses!$D:$D, A9, Responses!$E:$E) -> 3.5096154 | C9: =IFERROR(ROUND(AVERAGEIF(Responses!$D:$D, A9, Responses!$F:$F), 0), "") -> 70 | D9: =COUNTIF(FinalQuestions!C:C, A9) -> 4 | E9: =SUMIFS(Responses!G:G, Responses!D:D, A9) / COUNTIFS(Responses!D:D, A9)*100 -> 49.038462 | F9: =IF(Table9[[#This Row],[AvgScore100]]>=80,"Low",IF(Table9[[#This Row],[AvgScore100]]>=70,"Medium","High")) -> Medium
A19: SoftControl | B19: AvgScore100
A20: Role Modelling | B20: =IFERROR(ROUND(AVERAGEIF(Responses!$D:$D, A2, Responses!$F:$F), 0), "") -> 75
A21: Discussability | B21: =IFERROR(ROUND(AVERAGEIF(Responses!$D:$D, A3, Responses!$F:$F), 0), "") -> 78
A22: Achievability | B22: =IFERROR(ROUND(AVERAGEIF(Responses!$D:$D, A4, Responses!$F:$F), 0), "") -> 72
A23: Enforcement | B23: =IFERROR(ROUND(AVERAGEIF(Responses!$D:$D, A5, Responses!$F:$F), 0), "") -> 75
A24: Clarity | B24: =IFERROR(ROUND(AVERAGEIF(Responses!$D:$D, A6, Responses!$F:$F), 0), "") -> 75
A25: Transparency | B25: =IFERROR(ROUND(AVERAGEIF(Responses!$D:$D, A7, Responses!$F:$F), 0), "") -> 75
A26: Commitment | B26: =IFERROR(ROUND(AVERAGEIF(Responses!$D:$D, A8, Responses!$F:$F), 0), "") -> 74
A27: Call Someone to Account | B27: =IFERROR(ROUND(AVERAGEIF(Responses!$D:$D, A9, Responses!$F:$F), 0), "") -> 70

Sheet SurveyForm
A1: Respondent ID | B1: R030
A2: Function | B2: Finance
A4: RespondentID | B4: QuestionID | C4: Question Text | D4: Response (user selects) | E4: Score_5 | F4: Score_100 | G4: SoftControl
A5: =$B$1 -> R030 | B5: {=INDEX(FinalQuestions!$A:$A, ROW()-3)} -> Q001 | C5: {=INDEX(FinalQuestions!$B:$B, ROW()-3)} -> I believe that my leaders and senior managers consistently act as positive role models, also when they are under time pressure or facing difficult trade‑offs. | D5: Agree | E5: =IF(D5="","",CHOOSE(MATCH(D5,{"Strongly Agree","Agree","Neutral","Disagree","Strongly Disagree"},0),5,4,3,2,1)) -> 4 | F5: =IF(E5="","",E5*20) -> 80 | G5: =_xlfn.XLOOKUP(B5,FinalQuestions!$A:$A,FinalQuestions!$C:$C,"") -> Role Modelling
A6: =$B$1 -> R030 | B6: {=INDEX(FinalQuestions!$A:$A, ROW()-3)} -> Q002 | C6: {=INDEX(FinalQuestions!$B:$B, ROW()-3)} -> Leaders openly emphasize the importance of doing things the right way, even under time pressure | D6: Agree | E6: =IF(D6="","",CHOOSE(MATCH(D6,{"Strongly Agree","Agree","Neutral","Disagree","Strongly Disagree"},0),5,4,3,2,1)) -> 4 | F6: =IF(E6="","",E6*20) -> 80 | G6: =_xlfn.XLOOKUP(B6,FinalQuestions!$A:$A,FinalQuestions!$C:$C,"") -> Role Modelling
A7: =$B$1 -> R030 | B7: {=INDEX(FinalQuestions!$A:$A, ROW()-3)} -> Q003 | C7: {=INDEX(FinalQuestions!$B:$B, ROW()-3)} -> All the seniors encourage employees to identify, escalate and report all the concerns in a timely manner | D7: Agree | E7: =IF(D7="","",CHOOSE(MATCH(D7,{"Strongly Agree","Agree","Neutral","Disagree","Strongly Disagree"},0),5,4,3,2,1)) -> 4 | F7: =IF(E7="","",E7*20) -> 80 | G7: =_xlfn.XLOOKUP(B7,FinalQuestions!$A:$A,FinalQuestions!$C:$C,"") -> Role Modelling
A8: =$B$1 -> R030 | B8: {=INDEX(FinalQuestions!$A:$A, ROW()-3)} -> Q004 | C8: {=INDEX(FinalQuestions!$B:$B, ROW()-3)} -> When decisions are made by leaders, potential and long-term implications are usually considered. | D8: Agree | E8: =IF(D8="","",CHOOSE(MATCH(D8,{"Strongly Agree","Agree","Neutral","Disagree","Strongly Disagree"},0),5,4,3,2,1)) -> 4 | F8: =IF(E8="","",E8*20) -> 80 | G8: =_xlfn.XLOOKUP(B8,FinalQuestions!$A:$A,FinalQuestions!$C:$C,"") -> Role Modelling
A9: =$B$1 -> R030 | B9: {=INDEX(FinalQuestions!$A:$A, ROW()-3)} -> Q005 | C9: {=INDEX(FinalQuestions!$B:$B, ROW()-3)} -> Differences of opinion are respected during discussions about judgments or decisions | D9: Agree | E9: =IF(D9="","",CHOOSE(MATCH(D9,{"Strongly Agree","Agree","Neutral","Disagree","Strongly Disagree"},0),5,4,3,2,1)) -> 4 | F9: =IF(E9="","",E9*20) -> 80 | G9: =_xlfn.XLOOKUP(B9,FinalQuestions!$A:$A,FinalQuestions!$C:$C,"") -> Discussability
A10: =$B$1 -> R030 | B10: {=INDEX(FinalQuestions!$A:$A, ROW()-3)} -> Q006 | C10: {=INDEX(FinalQuestions!$B:$B, ROW()-3)} -> I can openly raise concerns without fear of negative consequences | D10: Agree | E10: =IF(D10="","",CHOOSE(MATCH(D10,{"Strongly Agree","Agree","Neutral","Disagree","Strongly Disagree"},0),5,4,3,2,1)) -> 4 | F10: =IF(E10="","",E10*20) -> 80 | G10: =_xlfn.XLOOKUP(B10,FinalQuestions!$A:$A,FinalQuestions!$C:$C,"") -> Discussability
A11: =$B$1 -> R030 | B11: {=INDEX(FinalQuestions!$A:$A, ROW()-3)} -> Q007 | C11: {=INDEX(FinalQuestions!$B:$B, ROW()-3)} -> Colleagues respond constructively when mistakes or concerns are raised management. | D11: Agree | E11: =IF(D11="","",CHOOSE(MATCH(D11,{"Strongly Agree","Agree","Neutral","Disagree","Strongly Disagree"},0),5,4,3,2,1)) -> 4 | F11: =IF(E11="","",E11*20) -> 80 | G11: =_xlfn.XLOOKUP(B11,FinalQuestions!$A:$A,FinalQuestions!$C:$C,"") -> Discussability
A12: =$B$1 -> R030 | B12: {=INDEX(FinalQuestions!$A:$A, ROW()-3)} -> Q008 | C12: {=INDEX(FinalQuestions!$B:$B, ROW()-3)} -> I feel comfortable escalating issues to Risk Management / Ethics & Independence / DPP when needed | D12: Agree | E12: =IF(D12="","",CHOOSE(MATCH(D12,{"Strongly Agree","Agree","Neutral","Disagree","Strongly Disagree"},0),5,4,3,2,1)) -> 4 | F12: =IF(E12="","",E12*20) -> 80 | G12: =_xlfn.XLOOKUP(B12,FinalQuestions!$A:$A,FinalQuestions!$C:$C,"") -> Discussability
A13: =$B$1 -> R030 | B13: {=INDEX(FinalQuestions!$A:$A, ROW()-3)} -> Q009 | C13: {=INDEX(FinalQuestions!$B:$B, ROW()-3)} -> I have received enough training to handle job‑related challenges effectively. | D13: Agree | E13: =IF(D13="","",CHOOSE(MATCH(D13,{"Strongly Agree","Agree","Neutral","Disagree","Strongly Disagree"},0),5,4,3,2,1)) -> 4 | F13: =IF(E13="","",E13*20) -> 80 | G13: =_xlfn.XLOOKUP(B13,FinalQuestions!$A:$A,FinalQuestions!$C:$C,"") -> Achievability
A14: =$B$1 -> R030 | B14: {=INDEX(FinalQuestions!$A:$A, ROW()-3)} -> Q010 | C14: {=INDEX(FinalQuestions!$B:$B, ROW()-3)} -> Within my team or department people have enough time and resources to do their job without taking unacceptable risks | D14: Agree | E14: =IF(D14="","",CHOOSE(MATCH(D14,{"Strongly Agree","Agree","Neutral","Disagree","Strongly Disagree"},0),5,4,3,2,1)) -> 4 | F14: =IF(E14="","",E14*20) -> 80 | G14: =_xlfn.XLOOKUP(B14,FinalQuestions!$A:$A,FinalQuestions!$C:$C,"") -> Achievability
A15: =$B$1 -> R030 | B15: {=INDEX(FinalQuestions!$A:$A, ROW()-3)} -> Q011 | C15: {=INDEX(FinalQuestions!$B:$B, ROW()-3)} -> People set targets that are achievable without compromising risk management policies, guidelines and procedures. | D15: Agree | E15: =IF(D15="","",CHOOSE(MATCH(D15,{"Strongly Agree","Agree","Neutral","Disagree","Strongly Disagree"},0),5,4,3,2,1)) -> 4 | F15: =IF(E15="","",E15*20) -> 80 | G15: =_xlfn.XLOOKUP(B15,FinalQuestions!$A:$A,FinalQuestions!$C:$C,"") -> Achievability
A16: =$B$1 -> R030 | B16: {=INDEX(FinalQuestions!$A:$A, ROW()-3)} -> Q012 | C16: {=INDEX(FinalQuestions!$B:$B, ROW()-3)} -> People visibly consider potential risks when making strategic decisions | D16: Agree | E16: =IF(D16="","",CHOOSE(MATCH(D16,{"Strongly Agree","Agree","Neutral","Disagree","Strongly Disagree"},0),5,4,3,2,1)) -> 4 | F16: =IF(E16="","",E16*20) -> 80 | G16: =_xlfn.XLOOKUP(B16,FinalQuestions!$A:$A,FinalQuestions!$C:$C,"") -> Achievability
... A36: =$B$1 -> R030 | B36: {=INDEX(FinalQuestions!$A:$A, ROW()-3)} -> Q032 | C36: {=INDEX(FinalQuestions!$B:$B, ROW()-3)} -> Team members are held to the same behavioral standards, no matter who they are. | D36: Strongly Agree | E36: =IF(D36="","",CHOOSE(MATCH(D36,{"Strongly Agree","Agree","Neutral","Disagree","Strongly Disagree"},0),5,4,3,2,1)) -> 5 | F36: =IF(E36="","",E36*20) -> 100 | G36: =_xlfn.XLOOKUP(B36,FinalQuestions!$A:$A,FinalQuestions!$C:$C,"") -> Call someone to account

Sheet Functions
A1: RespondentID | B1: Function
A2: R001 | B2: HR
A3: R002 | B3: Finance
A4: R003 | B4: HR
A5: R004 | B5: Operations
A6: R005 | B6: Operations
A7: R006 | B7: Audit
A8: R007 | B8: Finance
A9: R008 | B9: HR
A10: R009 | B10: Audit
A11: R010 | B11: IT
A12: R011 | B12: Sales
... A26: R025 | B26: Finance

Sheet Dimension Sheet
A1: Dimension | B1: AvgScore_100 | C1: Favorable% | D1: Unfavorable% | E1: Neutral% | F1: People_Unfavorable | G1: Total_Responses
A2: =_xlfn.XLOOKUP(Table7[[#This Row],[QuestionID]], FinalQuestions!$A:$A, FinalQuestions!$D:$D,"") -> Leadership Example‑Setting in Risk Management | B2: =IFERROR(ROUND(AVERAGEIFS(Responses!$F:$F,Responses!$H:$H,$A2),0),0) -> 71 | C2: =IFERROR(SUMIFS(Responses!$G:$G,Responses!$H:$H,$A2)/COUNTIFS(Responses!$H:$H,$A2),0) -> 0.46153846 | D2: =IFERROR((COUNTIFS(Responses!$H:$H,$A2,Responses!$C:$C,"Disagree")+COUNTIFS(Responses!$H:$H,$A2,Responses!$C:$C,"Strongly Disagree"))/COUNTIFS(Responses!$H:$H,$A2),0) -> 0.11538462 | E2: =1-C2-D2 -> 0.42307692 | F2: {=_xlfn.LET(_xlpm.dim,$A2,_xlpm.bad,_xlfn._xlws.FILTER(Responses!$A:$A,(Responses!$H:$H=_xlpm.dim)*((Responses!$C:$C="Disagree")+(Responses!$C:$C="Strongly Disagree"))),COUNTA(_xlfn.UNIQUE(_xlpm.bad)))} -> 3 | G2: =COUNTIFS(Responses!$H:$H,$A2) -> 26
A3: =_xlfn.XLOOKUP(Table7[[#This Row],[QuestionID]], FinalQuestions!$A:$A, FinalQuestions!$D:$D,"") -> Executive Commitment to Risk Culture | B3: =IFERROR(ROUND(AVERAGEIFS(Responses!$F:$F,Responses!$H:$H,$A3),0),0) -> 76 | C3: =IFERROR(SUMIFS(Responses!$G:$G,Responses!$H:$H,$A3)/COUNTIFS(Responses!$H:$H,$A3),0) -> 0.61538462 | D3: =IFERROR((COUNTIFS(Responses!$H:$H,$A3,Responses!$C:$C,"Disagree")+COUNTIFS(Responses!$H:$H,$A3,Responses!$C:$C,"Strongly Disagree"))/COUNTIFS(Responses!$H:$H,$A3),0) -> 0.076923077 | E3: =1-C3-D3 -> 0.30769231 | F3: {=_xlfn.LET(_xlpm.dim,$A3,_xlpm.bad,_xlfn._xlws.FILTER(Responses!$A:$A,(Responses!$H:$H=_xlpm.dim)*((Responses!$C:$C="Disagree")+(Responses!$C:$C="Strongly Disagree"))),COUNTA(_xlfn.UNIQUE(_xlpm.bad)))} -> 2 | G3: =COUNTIFS(Responses!$H:$H,$A3) -> 26
A4: =_xlfn.XLOOKUP(Table7[[#This Row],[QuestionID]], FinalQuestions!$A:$A, FinalQuestions!$D:$D,"") -> Leadership Encouragement to Escalate Risks | B4: =IFERROR(ROUND(AVERAGEIFS(Responses!$F:$F,Responses!$H:$H,$A4),0),0) -> 82 | C4: =IFERROR(SUMIFS(Responses!$G:$G,Responses!$H:$H,$A4)/COUNTIFS(Responses!$H:$H,$A4),0) -> 0.73076923 | D4: =IFERROR((COUNTIFS(Responses!$H:$H,$A4,Responses!$C:$C,"Disagree")+COUNTIFS(Responses!$H:$H,$A4,Responses!$C:$C,"Strongly Disagree"))/COUNTIFS(Responses!$H:$H,$A4),0) -> 0 | E4: =1-C4-D4 -> 0.26923077 | F4: {=_xlfn.LET(_xlpm.dim,$A4,_xlpm.bad,_xlfn._xlws.FILTER(Responses!$A:$A,(Responses!$H:$H=_xlpm.dim)*((Responses!$C:$C="Disagree")+(Responses!$C:$C="Strongly Disagree"))),COUNTA(_xlfn.UNIQUE(_xlpm.bad)))} -> 1 | G4: =COUNTIFS(Responses!$H:$H,$A4) -> 26
A5: =_xlfn.XLOOKUP(Table7[[#This Row],[QuestionID]], FinalQuestions!$A:$A, FinalQuestions!$D:$D,"") -> Long-Term Decision Awareness | B5: =IFERROR(ROUND(AVERAGEIFS(Responses!$F:$F,Responses!$H:$H,$A5),0),0) -> 73 | C5: =IFERROR(SUMIFS(Responses!$G:$G,Responses!$H:$H,$A5)/COUNTIFS(Responses!$H:$H,$A5),0) -> 0.53846154 | D5: =IFERROR((COUNTIFS(Responses!$H:$H,$A5,Responses!$C:$C,"Disagree")+COUNTIFS(Responses!$H:$H,$A5,Responses!$C:$C,"Strongly Disagree"))/COUNTIFS(Responses!$H:$H,$A5),0) -> 0.15384615 | E5: =1-C5-D5 -> 0.30769231 | F5: {=_xlfn.LET(_xlpm.dim,$A5,_xlpm.bad,_xlfn._xlws.FILTER(Responses!$A:$A,(Responses!$H:$H=_xlpm.dim)*((Responses!$C:$C="Disagree")+(Responses!$C:$C="Strongly Disagree"))),COUNTA(_xlfn.UNIQUE(_xlpm.bad)))} -> 4 | G5: =COUNTIFS(Responses!$H:$H,$A5) -> 26
A6: =_xlfn.XLOOKUP(Table7[[#This Row],[QuestionID]], FinalQuestions!$A:$A, FinalQuestions!$D:$D,"") -> Openness to Discussions | B6: =IFERROR(ROUND(AVERAGEIFS(Responses!$F:$F,Responses!$H:$H,$A6),0),0) -> 72 | C6: =IFERROR(SUMIFS(Responses!$G:$G,Responses!$H:$H,$A6)/COUNTIFS(Responses!$H:$H,$A6),0) -> 0.5 | D6: =IFERROR((COUNTIFS(Responses!$H:$H,$A6,Responses!$C:$C,"Disagree")+COUNTIFS(Responses!$H:$H,$A6,Responses!$C:$C,"Strongly Disagree"))/COUNTIFS(Responses!$H:$H,$A6),0) -> 0.11538462 | E6: =1-C6-D6 -> 0.38461538 | F6: {=_xlfn.LET(_xlpm.dim,$A6,_xlpm.bad,_xlfn._xlws.FILTER(Responses!$A:$A,(Responses!$H:$H=_xlpm.dim)*((Responses!$C:$C="Disagree")+(Responses!$C:$C="Strongly Disagree"))),COUNTA(_xlfn.UNIQUE(_xlpm.bad)))} -> 3 | G6: =COUNTIFS(Responses!$H:$H, $A3) -> 26
A7: =_xlfn.XLOOKUP(Table7[[#This Row],[QuestionID]], FinalQuestions!$A:$A, FinalQuestions!$D:$D,"") -> Access to Guidance | B7: =IFERROR(ROUND(AVERAGEIFS(Responses!$F:$F,Responses!$H:$H,$A7),0),0) -> 78 | C7: =IFERROR(SUMIFS(Responses!$G:$G,Responses!$H:$H,$A7)/COUNTIFS(Responses!$H:$H,$A7),0) -> 0.53846154 | D7: =IFERROR((COUNTIFS(Responses!$H:$H,$A7,Responses!$C:$C,"Disagree")+COUNTIFS(Responses!$H:$H,$A7,Responses!$C:$C,"Strongly Disagree"))/COUNTIFS(Responses!$H:$H,$A7),0) -> 0.038461538 | E7: =1-C7-D7 -> 0.42307692 | F7: {=_xlfn.LET(_xlpm.dim,$A7,_xlpm.bad,_xlfn._xlws.FILTER(Responses!$A:$A,(Responses!$H:$H=_xlpm.dim)*((Responses!$C:$C="Disagree")+(Responses!$C:$C="Strongly Disagree"))),COUNTA(_xlfn.UNIQUE(_xlpm.bad)))} -> 1 | G7: =COUNTIFS(Responses!$H:$H, $A4) -> 26
A8: =_xlfn.XLOOKUP(Table7[[#This Row],[QuestionID]], FinalQuestions!$A:$A, FinalQuestions!$D:$D,"") -> Openness to Sharing Opinions | B8: =IFERROR(ROUND(AVERAGEIFS(Responses!$F:$F,Responses!$H:$H,$A8),0),0) -> 82 | C8: =IFERROR(SUMIFS(Responses!$G:$G,Responses!$H:$H,$A8)/COUNTIFS(Responses!$H:$H,$A8),0) -> 0.73076923 | D8: =IFERROR((COUNTIFS(Responses!$H:$H,$A8,Responses!$C:$C,"Disagree")+COUNTIFS(Responses!$H:$H,$A8,Responses!$C:$C,"Strongly Disagree"))/COUNTIFS(Responses!$H:$H,$A8),0) -> 0.038461538 | E8: =1-C8-D8 -> 0.23076923 | F8: {=_xlfn.LET(_xlpm.dim,$A8,_xlpm.bad,_xlfn._xlws.FILTER(Responses!$A:$A,(Responses!$H:$H=_xlpm.dim)*((Responses!$C:$C="Disagree")+(Responses!$C:$C="Strongly Disagree"))),COUNTA(_xlfn.UNIQUE(_xlpm.bad)))} -> 1 | G8: =COUNTIFS(Responses!$H:$H, $A5) -> 26
